<?xml version="1.0"?> 
<robot name="simplecar">
    <!-- Colors --> 
    <material name="black"> 
        <color rgba="0 0 0 1"/>
    </material>
    <material name="blue"> 
        <color rgba="0.6 0.7 0.8 1"/>
    </material>


    <!-- Base Frame of Arm --> 
    <link name="base_link">
        <visual> 
            <geometry> 
                <box size="0.3 0.3 0.3"/>
            </geometry>
            <material name="blue"/>
        </visual>
        <inertial>
            <mass value="6"/>
            <inertia ixx="0.1" ixy="0" ixz="0" iyy="0.1" iyz="0.0" izz="0.1"/>
        </inertial> 
    </link> 


    <!-- Link_0 -->
    <link name="link_0">
        <visual> 
            <geometry> 
                <cylinder length="1" radius="0.1"/>
            </geometry>
            <origin xyz="0.3 0 0" rpy="0 1 0" />
            <material name="black"/>
        </visual>
        <collision> 
             <geometry> 
                <cylinder length="0.05" radius="0.1"/>
            </geometry>
            <origin xyz="0.3 0 0" rpy="0 1 0" />
        </collision> 
        <inertial> 
            <origin xyz="0.3 0 0" rpy="0 1 0" />
            <mass value="0.3"/>
            <inertia ixx="0.4" ixy="0" ixz="0" iyy="0.4" iyz="0.0" izz="0.2"/>
        </inertial> 
    </link>

    <joint name="base_to_L0_joint" type="continuous">
        <parent link="base_link"/>
        <child link="link_0"/> 
        <axis xyz="0 0 1"/>
        <origin xyz="0.3 0.2 0"/>
    </joint>
    <!-- Link_1-->
    <link name="link_1">
        <visual> 
            <geometry> 
                <cylinder length="1" radius="0.1"/>
            </geometry>
            <origin xyz="1.3 0 0.1" rpy="0 1 0" />
            <material name="black"/>
        </visual>
        <collision> 
             <geometry> 
                <cylinder length="0.05" radius="0.1"/>
            </geometry>
            <origin xyz="1.3 0 0" rpy="0 1 0" />
        </collision> 
        <inertial> 
            <origin xyz="1.3 0 0" rpy="0 1 0" />
            <mass value="0.3"/>
            <inertia ixx="0.4" ixy="0" ixz="0" iyy="0.4" iyz="0.0" izz="0.2"/>
        </inertial> 
    </link> 
    <joint name="L0_to_L1" type="continuos">
        <parent link="link_0"/>
        <child link="link_1"/> 
        <axis xyz="0 0 1"/>
        <origin xyz="1.3 0.0 0"/>
    </joint>
</robot>
